Workbook
Name AdministrasiS: GL!$G$2864:$G$2865
Name Aktkeu: GL!$G$2214:$G$2267
Name ASF: GL!$G$2436:$G$2485
Name Audio: GL!$G$1406:$G$1460
Name Bakademik1: GL!$K$842:$K$1089
Name Bakademik2: GL!$G$842:$G$1089
Name BBantuan1: GL!$K$2856:$K$2865
Name BBantuan2: GL!$G$2856:$G$2865
Name BDaksos1: GL!$K$1090:$K$1355
Name BDaksos2: GL!$G$1090:$G$1355
Name BDepresiasi1: GL!$K$2808:$K$2855
Name BDepresiasi2: GL!$G$2808:$G$2855
Name BDukunganAka1: GL!$K$1356:$K$1460
Name BDukunganAka2: GL!$G$1356:$G$1460
Name BeasiswaSa: GL!$G$2862:$G$2863
Name Bimbangankonseling: GL!$G$1703:$G$1752
Name BKegiatanSantri1: GL!$K$1461:$K$2090
Name BKegiatanSantri2: GL!$G$1461:$G$2090
Name BLayananAsrama1: GL!$K$2874:$K$3039
Name BlayananAsrama2: GL!$G$2874:$G$3039
Name BPemeliharaan1: GL!$K$2436:$K$2807
Name BPemeliharaan2: GL!$G$2436:$G$2807
Name BPenjualan1: GL!$K$2866:$K$2873
Name BPenjualan2: GL!$G$2866:$G$2873
Name Buku: GL!$G$2868:$G$2870
Name CDAK1: CD!$I$12:$I$1989
Name CDAK2: CD!$F$12:$F$1989
Name COA: [1]NASo!$A$8:$F$282
Name CRAK1: CR!$I$12:$I$1000
Name CRAK2: CR!$G$12:$G$1000
Name Daksan: GL!$G$2036:$G$2042
Name Dakwah: GL!$G$1090:$G$1149
Name DepB: GL!$G$2808:$G$2816
Name DepEq: GL!$G$2827:$G$2835
Name DepFu: GL!$G$2836:$G$2845
Name DepInf: GL!$G$2817:$G$2826
Name DepLi: GL!$G$2850:$G$2853
Name Depoth: GL!$G$2854:$G$2855
Name Depv: GL!$G$2846:$G$2849
Name DukunganInstitusi1: GL!$K$2091:$K$2435
Name DukunganInstitusi2: GL!$G$2091:$G$2435
Name Executive: GL!$G$2091:$G$2148
Name Humas: GL!$G$1283:$G$1355
Name InformasiTeknologi: GL!$G$2384:$G$2435
Name JMAK1: JM!$I$12:$I$1005
Name JMAK2: JM!$G$12:$G$1005
Name JMAK3: JM!$F$12:$F$1005
Name Jummiyah: GL!$G$1812:$G$2035
Name Keamanan: GL!$G$2700:$G$2753
Name KepengasuhanMA: GL!$G$1621:$G$1702
Name Kepengasuhanmts: GL!$G$1541:$G$1620
Name KepengasuhanSDITQ: GL!$G$1461:$G$1540
Name Kesehatansantri: GL!$G$1753:$G$1811
Name KK: GL!$G$2486:$G$2545
Name KODEAK: CD!$I$12:$I$989
Name Layanankamar: GL!$G$2989:$G$3039
Name layananlaundry: GL!$G$2933:$G$2988
Name Layananmakanan: GL!$G$2874:$G$2932
Name Ledger: '[1]Buku Besar'!$A$7:$J$134
Name Litbang: GL!$G$2149:$G$2213

Sheet IN
A1: PESANTREN ISLAM AL IRSYAD TENGARAN 6 BONDOWOSO
A2: INPUT LAPORAN KEUANGAN
A3: TAHUN PELAJARAN 2025 - 2026 | C3: EDUCATION YEAR 2025 - 2026
C4: =IF($B$5="","","Laporan Keuangan "&TEXT($B$5,"MMMM YYYY")) -> Laporan Keuangan June 2026 | D4: =IF($B$5="","","Financial Statement "&TEXT($B$5,"MMM YYYY")) -> Financial Statement Jun 2026
A5: TANGGAL NERACA | B5: 46203 | C5: =TEXT(_xlnm.Criteria,"dd mmmm yyyy") -> 30 June 2026 | D5: =_xlnm.Criteria -> 46203
A6: AWAL TAHUN PELAJARAN | B6: 45839
A7: AKHIR TAHUN PELAJARAN | B7: 46203
C8: =TEXT(B9,"dd mmmm yyyy") -> 31 May 2026 | D8: =B9 -> 46173
A9: PERBANDINGAN DENGAN | B9: =IF(_xlnm.Criteria=0,"",EOMONTH($B$5,-1)) -> 46173 | C9: =IF(C8="","","(Dengan perbandingan informasi keuangan untuk bulan yang berakhir "&TEXT(C8,"DD MMMM YYYY")&" /") -> (Dengan perbandingan informasi keuangan untuk bulan yang berakhir 31 May 2026 /
C10: =IF(D8="","","With Comparative financial information for the month ended "&TEXT(D8,"MMM DD, YYYY")&" )") -> With Comparative financial information for the month ended May 31, 2026 )

Sheet Cover Dp
L1: 1
A24: PESANTREN ISLAM AL-IRSYAD
A25: TENGARAN 6 - BONDOWOSO
A29: LAPORAN KEUANGAN / FINANCIAL STATEMENTS
A30: =IN!A3 -> TAHUN PELAJARAN 2025 - 2026 | F30: / | G30: =IN!C3 -> EDUCATION YEAR 2025 - 2026
A31: Untuk Bulan yang Berakhir / For the Month Ended
A32: =IN!C5 -> 30 June 2026 | F32: / | G32: =IN!D5 -> 46203
A33: =IN!C9 -> (Dengan perbandingan informasi keuangan untuk bulan yang berakhir 31 May 2026 /
A34: =IN!C10 -> With Comparative financial information for the month ended May 31, 2026 )

Sheet Cover Blkg
K1: 1
A41: PESANTREN ISLAM AL-IRSYAD
A42: TENGARAN 6 - BONDOWOSO
A46: =IN!C4 -> Laporan Keuangan June 2026 | F46: =IN!D4 -> Financial Statement Jun 2026

Sheet TC
B12: PESANTREN ISLAM AL-IRSYAD, TENGARAN
B14: Laporan Keuangan / Financial Statements
B15: Untuk Bulan yang Berakhir / For the Month Ended
F16: =IN!C5 -> 30 June 2026 | O16: / | P16: =IN!D5 -> 46203
B17: =IN!C9 -> (Dengan perbandingan informasi keuangan untuk bulan yang berakhir 31 May 2026 /
B18: =IN!C10 -> With Comparative financial information for the month ended May 31, 2026 )
B21: Daftar isi | M21: Halaman / Page | V21: Table contents
B23: Kata pengantar dari manajemen | M23: …………………………………………………. | Q23: …………………………………………………. | AF23: Message from the management | AI23: =IF(AH23="ok",1,"")
B24: Grafik perubahan aset bersih tidak terikat | M24: ……………………………………… | O24: 1 | Q24: …………………………………. | AF24: Graphic of changes in unrestricted net assets | AI24: =IF(AH24="ok",1,"")
B25: Laporan posisi keuangan | M25: ………………………………………………………. | O25: 2 | Q25: …………………………………………………. | AF25: Statements of financial position | AI25: =IF(AH25="ok",1,"")
B26: Laporan pendapatan, beban dan perubahan aset bersih tidak terikat | M26: …… | O26: 3 | AF26: ...Statements of revenues, expenses and changes in unrestricted net assets | AI26: =IF(AH26="ok",1,"")
B27: Laporan perubahan aset bersih | M27: ………………………………………………. | O27: 4 | Q27: ……………………………………………. | AF27: Statements of changes in net assets | AI27: =IF(AH27="ok",1,"")
B28: Laporan arus kas | M28: ………………………………………………………………….. | O28: 5 | Q28: ………………………………………………………………… | AF28: Statements of cash flow | AI28: =IF(AH28="ok",1,"")
B29: Catatan atas laporan keuangan | M29: …………………………………………………. | N29: 6 - 16 | Q29: ……………………………………………………. | AF29: Notes to financial statements | AI29: =IF(AH29="ok",1,"")
B30: Informasi tambahan | AF30: Supplementary information | AI30: =IF(AH30="ok",1,"")
B31: Lampiran 1 | E31: Rincian piutang uang pendidikan | M31: ………………………………….. | N31: 17 - 26 | Q31: ………………………………. | AC31: Details of tuition and fee receivable | AF31: Appendix 1 | AI31: =IF(AH31="ok",1,"")
B32: Lampiran 2 | E32: Rincian piutang lain lain | M32: ………………………………………….. | N32: 27 - 26 | Q32: …………………………………….. | AC32: Details of others receivables | AF32: Appendix 2 | AI32: =IF(AH32="ok",1,"")
B33: Lampiran 3 | E33: Rincian persediaan | M33: ……………………………………………… | N33: 27 - 29 | Q33: ………………………………………………. | AC33: Details of inventories | AF33: Appendix 3 | AI33: =IF(AH33="ok",1,"")
B34: Lampiran 4 | E34: Rincian aset tetap | M34: …………………………………………… | N34: 30 - 40 | Q34: ………………………………………………. | AC34: Details of fixed assets | AF34: Appendix 4 | AI34: =IF(AH34="ok",1,"")
B35: Lampiran 5 | E35: Rincian titipan uang pendidikan | M35: ……………………………………. | N35: 41 - 43 | Q35: …………………………………. | AC35: Details of tuition and fee deposits | AF35: Appendix 5 | AI35: =IF(AH35="ok",1,"")
B36: Lampiran 6 | E36: Rincian titipan lain lain | M36: …………………………………………… | N36: 44 - 49 | Q36: …………………………………………. | AC36: Details of other deposits | AF36: Appendix 6 | AI36: =IF(AH36="ok",1,"")
B37: Lampiran 7 | E37: Rincian hutang lain lain | M37: …………………………………………… | O37: 50 | Q37: …………………………………………. | AC37: Details of other paybles | AF37: Appendix 7 | AI37: =IF(AH37="ok",1,"")
E38: Rincian biaya masih harus dibayar | M38: …………………………………………… | O38: 51 | Q38: …………………………………………. | AC38: Details of accrued expenses | AI38: =IF(AH38="ok",1,"")
B39: Lampiran 8 | E39: Rincian aset bersih terikat | M39: ………………………………………….. | O39: 52 | Q39: ……………………………………. | AC39: Details of restricted net assets | AF39: Appendix 8 | AI39: =IF(AH39="ok",1,"")
B40: Lampiran 9 | E40: Rincian pendapatan dan keuntungan tidak terikat | M40: ………………………………………….. | O40: 53 | Q40: ………………….. | AC40: Details of unrestricted revenues and gains | AF40: Appendix 9 | AI40: =IF(AH40="ok",1,"")
B41: Lampiran 10 | E41: Rincian beban dan kerugian | M41: ………………………………………….. | O41: 54 | Q41: …………………………………….. | AC41: Details of expenses and loss | AF41: Appendix 10 | AI41: =IF(AH41="ok",1,"")
B42: Lampiran 11 | E42: Rincian beban dan kerugian menurut klasifikasi sifat | AC42: Details of expenses and loss by natural classification | AF42: Appendix 11 | AI42: =IF(AH42="ok",1,"")
E43: dengan fungsional | M43: ……………………………………………….. | N43: 55 - 56 | Q43: ……………………………………… | AC43: with fuctional classification | AI43: =IF(AH43="ok",1,"")
B44: Informasi tambahan untuk usaha pelengkap | AF44: Supplementary information for auxiliary enterprises | AI44: =IF(AH44="ok",1,"")
B45: Lampiran 12 | E45: Laporan posisi keuangan usaha pelengkap | M45: ……………………….. | O45: 57 | Q45: ……….. | AC45: Statements of auxiliary enterprises financial position | AF45: Appendix 12 | AI45: =IF(AH45="ok",1,"")
B46: Lampiran 13 | E46: Rincian pendapatan dan beban usaha pelengkap | M46: …………….. | O46: 58 | Q46: ……. | AC46: Details of auxiliary enterprises revenues and expenses | AF46: Appendix 13 | AI46: =IF(AH46="ok",1,"")
B47: Lampiran 14 | E47: Rincian posisi keuangan - usaha pelengkap | M47: ……………………….. | N47: 59 - 63 | AC47: ….Details of statement financial position - auxiliary enterprises | AF47: Appendix 14 | AI47: =IF(AH47="ok",1,"")
B48: Lampiran 15 | E48: Rincian piutang pembiayaan 1 - usaha pelengkap | M48: …………….. | O48: 64 | AC48: Details of financing 1 account receivable - auxiliary enterprises | AF48: Appendix 15 | AI48: =IF(AH48="ok",1,"")
B49: Lampiran 16 | E49: Rincian piutang pembiayaan 2 - usaha pelengkap | M49: …………….. | O49: 65 | AC49: Details of financing 2 account receivable - auxiliary enterprises | AF49: Appendix 16 | AI49: =IF(AH49="ok",1,"")
B50: Lampiran 17 | E50: Rincian aset tetap - usaha pelengkap | M50: ……………………….. | N50: 66 - 67 | Q50: ………………….. | AC50: Details of fixed assets - auxiliary enterprises | AF50: Appendix 17 | AI50: =IF(AH50="ok",1,"")
B51: Lampiran 18 | E51: Rincian titipan simpanan anggota - usaha pelengkap | M51: …………….. | O51: 68 | AC51: ....Details of member's saving deposit - auxiliary enterprises | AF51: Appendix 18 | AI51: =IF(AH51="ok",1,"")
B52: Lampiran 19 | E52: Rincian hutang usaha Amin Mart - usaha pelengkap | M52: …………….. | O52: 70 | AC52: ...Details of Amin Mart account payables auxiliary enterprises | AF52: Appendix 19 | AI52: =IF(AH52="ok",1,"")
B53: Halaman kosong | M53: …………………………………………………………………. | O53: 71 | Q53: ………………………………………………………………………………. | AF53: Blank page | AI53: =IF(AH53="ok",1,"")
AI54: =SUM(AI23:AI53) -> 0
B55: Kata pengantar dari manajemen | M55: …………………………………………………. | Q55: …………………………………………………. | AF55: Message from the management
...

Sheet Grafik
A1: =IN!A1 -> PESANTREN ISLAM AL IRSYAD TENGARAN 6 BONDOWOSO
A3: II. GRAFIK PERUBAHAN ASET BERSIH TIDAK TERIKAT / GRAPHIC OF CHANGES IN UNRESTRICTED NET ASSETS
A45: Tahun pendidikan 2025 - 2026 (Juli 2025 - Juni 2026) / Education Year 2025- 2026 (July 2025 - June 2026)
A46: Uraian / | C46: Juli 2025 / | D46: Agustus 2025 / | E46: September 2025 / | F46: Oktober 2025/ | G46: Nopember 2025 / | H46: Desember 2025 / | I46: Januari 2026 / | J46: Februari 2026 / | K46: Maret 2026 / | L46: April 2026 / | M46: Mei 2026 / | N46: Juni 2026 / | O46: Jumlah /
A47: Description | C47: July 2025 | D47: August 2025 | E47: September 2025 | F47: October 2025 | G47: November 2025 | H47: December 2025 | I47: January 2026 | J47: February 2026 | K47: March 2026 | L47: April 2026 | M47: May 2026 | N47: June 2026 | O47: Total
A48: Pendapatan, keuntungan & dukungan lain / | B48: 0
A49: Revenues, gains & others support | B49: 0 | C49: 2944636096 | D49: 1010692073 | E49: 943787100 | F49: 1083368899 | G49: 1097743827 | H49: 812104650 | I49: 1445806630 | J49: 7.4180451e+08 | K49: 630681247 | L49: 707461450 | M49: 801827018 | N49: =LR!E58 -> 641150550 | O49: =SUM(C49:N49) -> 1.2861064e+10
A50: Beban & kerugian / | B50: 0
A51: Expenses & losses | B51: 0 | C51: 6.3391583e+08 | D51: 9.7570735e+08 | E51: 1.0586135e+09 | F51: 1.104388e+09 | G51: 7.6123705e+08 | H51: 7.1287737e+08 | I51: 7.4123915e+08 | J51: 8.0452115e+08 | K51: 9.5874558e+08 | L51: 7.4904215e+08 | M51: 9.5371266e+08 | N51: =LR!E75 -> 6.6987422e+08 | O51: =SUM(C51:N51) -> 1.0123874e+10
A52: Kenaikan ( penurunan ) /
A53: Increase ( decrease ) | B53: 0 | C53: =C49-C51 -> 2.3107203e+09 | D53: =D49-D51 -> 34984718 | E53: =E49-E51 -> -1.1482641e+08 | F53: =F49-F51 -> -21019071 | G53: =G49-G51 -> 3.3650677e+08 | H53: =H49-H51 -> 99227278 | I53: =I49-I51 -> 7.0456748e+08 | J53: =J49-J51 -> -62716636 | ... O53: =O49-O51 -> 2.7371901e+09
O54: ='[2]LR '!J82-O53 -> 2.0558689e+09
A64: =IN!C4 -> Laporan Keuangan June 2026 | H64: 1 | O64: =IN!D4 -> Financial Statement Jun 2026

Sheet NRC
B2: PESANTREN ISLAM AL-IRSYAD TENGARAN 6 BONDOWOSO
B4: LAPORAN POSISI KEUANGAN | K4: STATEMENTS OF FINANCIAL POSITION
B5: =IN!C5 -> 30 June 2026 | I5: =IN!D5 -> 46203
C6: =IN!C9 -> (Dengan perbandingan informasi keuangan untuk bulan yang berakhir 31 May 2026 / | K6: =IN!C10 -> With Comparative financial information for the month ended May 31, 2026 )
B7: (Disajikan dalam rupiah) | K7: (Expressed in rupiah)
B9: Pos - pos | E9: =IN!C5&"/" -> 30 June 2026/ | F9: Catatan / | G9: =IN!C8&"/" -> 31 May 2026/ | H9: Kenaikan/Penurunan | I9: Accounts
E10: =IN!D5 -> 46203 | F10: Notes | G10: =IN!D8 -> 46173
C11: Aset | J11: Assets
C12: Aset Lancar | J12: Current Assets
C13: Kas dan setara kas | E13: =CLK!Q152 -> 3.1284258e+09 | F13: 2 | G13: =CLK!X152 -> 3.0051166e+09 | H13: =E13-G13 -> 123309192 | J13: Cash and Cash Equivalents
C14: Piutang aktivitas - bersih | F14: 3 | J14: Account receivable - net
C15: אּ | D15: Piutang uang pendidikan - bersih | E15: =CLK!Q170 -> 847774000 | G15: =CLK!X170 -> 830206000 | H15: =E15-G15 -> 17568000 | I15: Tuition & fee receivable - net | J15: אּ
C16: אּ | D16: Piutang sumbangan - bersih | E16: =CLK!Q184 -> 0 | G16: =CLK!X184 -> 0 | H16: =E16-G16 -> 0 | I16: Contributions receivable - net | J16: אּ
C17: אּ | D17: Piutang usaha pelengkap - bersih | E17: =CLK!Q202 -> 140077350 | G17: =CLK!X202 -> 73712800 | H17: =E17-G17 -> 66364550 | I17: Auxiliary enterprises receiable net | J17: אּ
E18: =SUM(E15:E17) -> 987851350 | G18: =SUM(G15:G17) -> 903918800 | H18: =E18-G18 -> 83932550 | L18: =[3]NRC!$E$18 -> 1014166450 | M18: =L18-G18 -> 110247650
C19: Piutang lain lain - bersih | E19: =CLK!Q222 -> 78023804 | F19: 4 | G19: =CLK!X222 -> 71027505 | H19: =E19-G19 -> 6996298.2 | J19: Others receivables - net
C20: Persediaan | E20: =CLK!Q249 -> 206952262 | F20: 5 | G20: =CLK!X249 -> 224288070 | H20: =E20-G20 -> -17335808 | J20: Inventories
C21: Pajak dibayar dimuka | E21: =CLK!Q264 -> 0 | G21: =CLK!X264 -> 0 | H21: 0 | J21: Prepaid tax
C22: Uang muka | E22: =CLK!Q308 -> 32400000 | G22: =CLK!X308 -> 32400000 | H22: =E22-G22 -> 0 | J22: Advance payments
C23: Beban dibayar dimuka | E23: =CLK!Q322 -> 9166665.7 | G23: =CLK!X322 -> 10833332 | H23: =E23-G23 -> -1666666.7 | J23: Prepaid expenses
C25: Jumlah Aset Lancar | E25: =E13+E18+E19+E20+E21+E22+E23 -> 4.4428198e+09 | G25: =G13+G18+G19+G20+G21+G22+G23 -> 4.2475843e+09 | H25: =E25-G25 -> 1.9523557e+08 | J25: Total Current Assets | L25: =[3]NRC!$E$25 -> 3.0301104e+09 | M25: =L25-G25 -> -1.2174739e+09 | N25: ='20'!H25 -> 4.4428198e+09 | O25: =E25-N25 -> 0
C26: Aset Tidak Lancar | J26: Non Current Assets
C27: Investasi pada unit usaha pesantren | J27: Investment in Auxiliary Enterprises
C28: Aset tetap - bersih | J28: Fixed assets - net
C29: אּ | D29: Harga Perolehan | E29: =CLK!AF347 -> 2.2996453e+10 | F29: 8 | G29: =CLK!AF382 -> 2.2988954e+10 | H29: =E29-G29 -> 7499000 | I29: Acquisition cost | J29: אּ
C30: אּ | D30: Akumulasi Penyusutan | E30: =-CLK!AF358 -> -3.7406288e+09 | F30: 8 | G30: =-CLK!AF394 -> -3.64738e+09 | H30: =E30-G30 -> -93248822 | I30: Accumulated depreciation | J30: אּ
E31: =SUM(E29:E30) -> 1.9255825e+10 | G31: =SUM(G29:G30) -> 1.9341574e+10 | H31: =E31-G31 -> -85749822 | L31: =[3]NRC!$E$34 -> 1.8772845e+10 | M31: =L31-G31 -> -5.687297e+08
C32: Aset lain lain | E32: =CLK!Q434 -> 10130900 | G32: =CLK!X434 -> 9899400 | H32: =E32-G32 -> 231500 | J32: Other assets
C34: Jumlah Aset Tidak Lancar | E34: =E32+E31+E27 -> 1.9265955e+10 | G34: =G32+G31+G27 -> 1.9351474e+10 | H34: =E34-G34 -> -85518322 | J34: Total Non Current Assets | N34: ='20'!H34 -> 1.9265955e+10 | O34: =E34-N34 -> 0.4600029
B36: Jumlah Aset | E36: =E34+E25 -> 2.3708775e+10 | G36: =G34+G25 -> 2.3599058e+10 | H36: =E36-G36 -> 1.0971724e+08 | I36: Total Assets | L36: =[3]NRC!$E$36 -> 2.1802955e+10 | M36: =L36-G36 -> -1.796103e+09
C37: Liabilitas dan Aset Bersih | J37: Liabilities and Net Assets
C38: Liabilitas Lancar | J38: Current Liabilities
C39: Hutang aktivitas | J39: Account payble
C40: אּ | D40: Hutang pendidikan | E40: =CLK!Q456 -> 127867575 | G40: =CLK!X448 -> 23819342 | H40: =E40-G40 -> 104048233 | I40: Education payble | J40: אּ
C41: אּ | D41: Hutang usaha pelengkap | E41: =CLK!Q464 -> 0 | G41: =CLK!X464 -> 0 | H41: =E41-G41 -> 0 | I41: Auxiliary enterprises payble | J41: אּ
C42: אּ | D42: Hutang perolehan aset tetap | E42: =CLK!Q472 -> 0 | G42: =CLK!X472 -> 0 | H42: 0 | I42: Fixed assets acquisition payble | J42: אּ
E43: =SUM(E40:E42) -> 127867575 | G43: =SUM(G40:G42) -> 23819342 | H43: 0
C44: Hutang titipan | J44: Deposit paybles
C45: אּ | D45: Titipan uang pendidikan | E45: =CLK!Q488 -> 178972000 | F45: 11 | G45: =CLK!X488 -> 121652000 | H45: =E45-G45 -> 57320000 | I45: Tuition & fee deposits | J45: אּ
C46: אּ | D46: Tabungan santri | E46: =CLK!Q491 -> 85600 | F46: 11 | G46: =CLK!X491 -> 101107200 | H46: =E46-G46 -> -101021600 | I46: Student saving | J46: אּ
...

Sheet LR
B2: PESANTREN ISLAM AL IRSYAD TENGARAN 6 BONDOWOSO
B4: LAPORAN PENDAPATAN, BEBAN DAN | O4: STATEMENTS OF REVENUES, EXPENSES AND
B5: PERUBAHAN ASET BERSIH TIDAK TERIKAT | O5: CHANGES IN UNRESTRICTED NET ASSETS
C6: ="Untuk Bulan yang Berakhir "&NRC!B5 -> Untuk Bulan yang Berakhir 30 June 2026 | I6: ="For The Month Ended "&TEXT(IN!D5,"MMM YYYY") -> For The Month Ended Jun 2026
C7: =NRC!C6 -> (Dengan perbandingan informasi keuangan untuk bulan yang berakhir 31 May 2026 / | O7: =IN!C10 -> With Comparative financial information for the month ended May 31, 2026 )
O8: =[4]IN!K31 -> #N/A
B9: (Disajikan dalam rupiah) | O9: (Expressed in rupiah)
C11: Pos - pos | E11: =NRC!E9 -> 30 June 2026/ | F11: % | G11: Catatan / | H11: =NRC!G9 -> 31 May 2026/ | I11: % | J11: Selisih | K11: ="sd "&(E11) -> sd 30 June 2026/ | L11: % | M11: Accounts | P11: Catatan / | Q11: Catatan / | R11: ="sd "&(H11) -> sd 31 May 2026/
E12: =NRC!E10 -> 46203 | G12: Notes | H12: =NRC!G10 -> 46173 | K12: =NRC!E10 -> 46203 | P12: Notes | Q12: Notes | R12: =H12 -> 46173
C13: Pendapatan dan keuntungan tidak terikat | N13: Unrestricted revenues & gains
C14: Pendapatan uang pendidikan | N14: Tuition and fees
C15: אּ | D15: SPP | E15: ='9'!D15 -> 547400000 | H15: ='9'!G15 -> 552500000 | J15: =E15-H15 -> -5100000 | K15: =E15+R15 -> 6692650000 | M15: Tuition | N15: אּ | R15: 6145250000
C16: אּ | D16: Ekstrakurikuler | E16: ='9'!D16 -> 0 | H16: ='9'!G16 -> 0 | K16: =E16+R16 -> 0 | M16: Extra curriculer | N16: אּ | R16: 0
C17: אּ | D17: Ujian akhir semester | E17: ='9'!D17 -> 0 | H17: ='9'!G17 -> 0 | K17: =E17+R17 -> 0 | M17: Examination fee | N17: אּ | R17: 0
C18: אּ | D18: Daftar ulang | E18: ='9'!D18 -> 0 | H18: ='9'!G18 -> 0 | K18: =E18+R18 -> 578289000 | M18: Enrollment fee | N18: אּ | R18: 578289000
C19: אּ | D19: Dana pengembangan | E19: ='9'!D19 -> 0 | H19: ='9'!G19 -> 0 | J19: =E19-H19 -> 0 | K19: =E19+R19 -> 1207500000 | M19: Deveopment fund | N19: אּ | R19: 1207500000
C20: אּ | D20: Kegiatan santri | E20: ='9'!D20 -> 0 | H20: ='9'!G20 -> 0 | J20: =E20-H20 -> 0 | K20: =E20+R20 -> 74100000 | M20: Student activity | N20: אּ | R20: 74100000
C21: אּ | D21: Pendaftaran santri baru | E21: ='9'!D21 -> 0 | H21: ='9'!G21 -> 0 | J21: =E21-H21 -> 0 | K21: =E21+R21 -> 22500000 | M21: Admission fee | N21: אּ | R21: 22500000
E22: =SUM(E15:E21) -> 547400000 | H22: =SUM(H15:H21) -> 552500000 | J22: =E22-H22 -> -5100000 | K22: =SUM(K15:K21) -> 8575039000 | R22: 8027639000
C23: אּ | D23: Dikurangi : Potongan Pendidikan | E23: =-'9'!D24 -> -3950000 | H23: =-'9'!G24 -> -4200000 | J23: =E23-H23 -> 250000 | K23: =E23+R23 -> -70768000 | M23: Less : scholarship | N23: אּ | R23: -66818000
E24: =SUM(E22:E23) -> 543450000 | H24: =SUM(H22:H23) -> 548300000 | J24: =E24-H24 -> -4850000 | K24: =SUM(K22:K23) -> 8504271000 | R24: 7960821000
C25: Bantuan | E25: ='9'!D36 -> 1000100 | H25: ='9'!G36 -> 168 | J25: =E25-H25 -> 999932 | K25: =E25+R25 -> 1031304.3 | L25: =K25/$K$58*100 -> 0.0080188103 | N25: Contributions | R25: 31204.33
C26: Sumbangan | J26: =E26-H26 -> 0 | K26: =E26+R26 -> 0 | L26: =K26/$K$58*100 -> 0 | N26: Grants | R26: 0
C27: Penjualan & layanan | E27: ='9'!D44 -> 50000 | H27: ='9'!G44 -> 414950 | J27: =E27-H27 -> -364950 | K27: =E27+R27 -> 10914450 | L27: =K27/$K$58*100 -> 0.084864285 | N27: Sales & services | R27: 10864450
C28: Penghasilan investasi | E28: 0 | H28: 0 | J28: =E28-H28 -> 0 | K28: =E28+R28 -> 0 | L28: =K28/$K$58*100 -> 0 | N28: Investment income | R28: 0
C29: Usaha pelengkap | J29: =E29-H29 -> 0 | K29: =E29+R29 -> 0 | L29: =K29/$K$58*100 -> 0 | N29: Auxiliary enterprises | R29: 0
C30: אּ | D30: Kantin 6 Mart | E30: ='9'!D47 -> 82572250 | H30: ='9'!G47 -> 129992100 | J30: =E30-H30 -> -47419850 | K30: =E30+R30 -> 1332016556 | L30: =K30/$K$58*100 -> 10.35697 | M30: Financing | N30: אּ | R30: 1249444306
C31: אּ | D31: Wartel | E31: 0 | H31: 0 | J31: =E31-H31 -> 0 | K31: =E31+R31 -> 0 | L31: =K31/$K$58*100 -> 0 | M31: Telphone cabin | N31: אּ | R31: 0
C32: אּ | D32: Kanten | E32: 0 | H32: 0 | J32: =E32-H32 -> 0 | K32: =E32+R32 -> 0 | L32: =K32/$K$58*100 -> 0 | M32: Canteen | N32: אּ | R32: 0
C33: אּ | D33: Foto copy | E33: 0 | H33: 0 | J33: =E33-H33 -> 0 | K33: =E33+R33 -> 0 | L33: =K33/$K$58*100 -> 0 | M33: Foto copy | R33: 0
C34: אּ | D34: Toko | E34: 0 | H34: 0 | J34: =E34-H34 -> 0 | K34: =E34+R34 -> 0 | L34: =K34/$K$58*100 -> 0 | M34: Barber shop | N34: אּ | R34: 0
C35: אּ | D35: Kantor | E35: ='[4]9'!E41+'[4]9'!E42 -> 0 | H35: 0 | J35: =E35-H35 -> 0 | K35: =E35+R35 -> 0 | L35: =K35/$K$58*100 -> 0 | M35: Office | N35: אּ | R35: 0
E36: =SUM(E30:E35) -> 82572250 | H36: =SUM(H30:H35) -> 129992100 | J36: =E36-H36 -> -47419850 | K36: =SUM(K30:K35) -> 1332016556 | R36: 1249444306
C37: Penghasilan lain lain & keuntungan | J37: =E37-H37 -> 0 | N37: Others income & gains
C38: אּ | D38: Keuntungan pelepasan Aset tetap | E38: 0 | H38: 0 | J38: =E38-H38 -> 0 | K38: =E38+R38 -> 0 | M38: Gains on disposal of fixed assets | N38: אּ | R38: 0
C39: אּ | D39: Keuntungan penjualan investasi | E39: 0 | H39: 0 | J39: =E39-H39 -> 0 | K39: =E39+R39 -> 0 | M39: Loss on sale invesment | N39: אּ | R39: 0
C40: אּ | D40: Keuntungan selisih kurs & lain-lain | E40: 0 | H40: 0 | J40: =E40-H40 -> 0 | K40: =E40+R40 -> 0 | M40: Gains on foreign exchange | N40: אּ | R40: 0
C41: אּ | D41: Penerimaan dan pembulatan lebih | E41: 0 | H41: 0 | J41: =E41-H41 -> 0 | K41: =E41+R41 -> 0 | M41: Excess payment and rounded | N41: אּ | R41: 0
C42: אּ | D42: Penerimaan piutang yang dihapus | E42: 0 | H42: 0 | J42: =E42-H42 -> 0 | K42: =E42+R42 -> 0 | M42: Recovery of write off of receivable | N42: אּ | R42: 0
C43: אּ | D43: Bagi hasil dari UP | E43: 0 | H43: 0 | J43: =E43-H43 -> 0 | K43: =E43+R43 -> 0 | M43: Profit sharinf from AE | R43: 0
...

Sheet PAB
B2: PESANTREN ISLAM AL IRSYAD TENGARAN 6 BONDOWOSO
B4: LAPORAN PERUBAHAN ASET BERSIH | L4: STATEMENTS OF CHANGES IN NET ASSETS
B5: =LR!C6 -> Untuk Bulan yang Berakhir 30 June 2026 | K5: =LR!I6 -> For The Month Ended Jun 2026 | L5: =[8]RL!O6 -> #N/A
B6: =LR!C7 -> (Dengan perbandingan informasi keuangan untuk bulan yang berakhir 31 May 2026 / | L6: =LR!O7 -> With Comparative financial information for the month ended May 31, 2026 )
L7: =[8]RL!O8 -> #N/A
B8: (Disajikan dalam rupiah) | L8: (Expressed in rupiah)
B10: =B5 -> Untuk Bulan yang Berakhir 30 June 2026 | K10: ="For The Month Ended "&TEXT(IN!D5,"MMM YYYY") -> For The Month Ended Jun 2026 | L10: =[8]IN!M23 -> #N/A
C11: Pos - pos | E11: Catatan / | F11: Tidak terikat / | G11: Terikat temporer / | H11: Terikat permanen / | I11: Jumlah / | J11: Accounts
E12: Notes | F12: Unrestricted | G12: Temporarily | H12: Permanently | I12: Total
G13: restricted | H13: restricted
C14: Pendapatan dan keuntungan | K14: Revenues & gains
C15: Pendapatan pendidikan | F15: =LR!E22 -> 547400000 | G15: 0 | H15: 0 | I15: =SUM(F15:H15) -> 547400000 | K15: Tuition and fees
C16: אּ | D16: Dikurangi : beasiswa | F16: =LR!E23 -> -3950000 | I16: =SUM(F16:H16) -> -3950000 | J16: Less : scholarship | K16: אּ
F17: =F15+F16 -> 543450000 | G17: =SUM(G15:G16) -> 0 | H17: =SUM(H15:H16) -> 0 | I17: =I15+I16 -> 543450000
C18: Sumbangan | F18: =LR!E25 -> 1000100 | H18: 0 | I18: =SUM(F18:H18) -> 1000100 | K18: Contributions
C19: Bantuan | F19: =LR!E26 -> 0 | G19: =CLK!N785 -> 500000 | I19: =SUM(F19:H19) -> 500000 | K19: Grants
C20: Penjualan & layanan | F20: =LR!E27 -> 50000 | I20: =SUM(F20:H20) -> 50000 | K20: Sales & services
C21: Penghasilan investasi | F21: =LR!E28 -> 0 | I21: =SUM(F21:H21) -> 0 | K21: Investment income
C22: Usaha pelengkap | F22: =LR!E36 -> 82572250 | I22: =SUM(F22:H22) -> 82572250 | K22: Auxiliary enterprises
C23: Penghasilan lain lain & keuntungan | F23: =LR!E45 -> 0 | I23: =SUM(F23:H23) -> 0 | K23: Others income & gains
C24: Jumlah pendapatan dan keuntungan | F24: =SUM(F17:F23) -> 627072350 | G24: =SUM(G17:G23) -> 500000 | H24: =SUM(H17:H23) -> 0 | I24: =SUM(I17:I23) -> 627572350 | K24: Total Revenues and gains
C26: Aset bersih yang dibebaskan | K26: Net assets released
C27: dari pembatasan | F27: =LR!E55 -> 14078200 | G27: =-CLK!S794 -> -14078200 | H27: 0 | I27: =SUM(F27:H27) -> 0 | K27: from restrictions
C29: Jumlah pendapatan, keuntungan | K29: Total revenues, gains
C30: dan dukungan lain | F30: =F27+F24 -> 641150550 | G30: =G27+G24 -> -13578200 | H30: =H27+H24 -> 0 | I30: =SUM(F30:H30) -> 627572350 | K30: and other support
C32: Beban dan kerugian | F32: =LR!E75 -> 6.6987422e+08 | G32: 0 | H32: 0 | I32: =SUM(F32:H32) -> 6.6987422e+08 | K32: Expenses and losses
C34: Kenaikan ( penurunan ) | K34: Increase ( decrease )
C35: Aset bersih | F35: =F30-F32 -> -28723668 | G35: =G30-G32 -> -13578200 | H35: =H30-H32 -> 0 | I35: =SUM(F35:H35) -> -42301868 | K35: net assets
C37: Aset bersih awal bulan | F37: =F73 -> 1.4999862e+10 | G37: =G73 -> 351222700 | H37: =H73 -> 6438063087 | I37: =SUM(F37:H37) -> 2.1789148e+10 | K37: Net assets at beginning of month
D38: Reklasifikasi | F38: 0 | I38: =SUM(F38:H38) -> 0 | J38: Reclassification
C40: Aset bersih akhir bulan | F40: =F35+F37 -> 1.4971139e+10 | G40: =G35+G37 -> 337644500 | H40: =H35+H37 -> 6438063087 | I40: =I35+I37 -> 2.1746846e+10 | J40: Net assets at end of month
F41: =NRC!E68-F40 -> 0.0099868774 | G41: =G40-NRC!E70 -> 0 | H41: =H40-NRC!E71 -> 0 | I41: =I40-NRC!E74 -> -0.0099830627
B43: ="Untuk Bulan yang Berakhir "&TEXT(IN!C8,"MMMm YYYY") -> Untuk Bulan yang Berakhir May 2026 | K43: ="For The Month Ended "&TEXT(IN!D8,"MMM YYYY") -> For The Month Ended May 2026 | L43: =[8]IN!M26 -> #N/A
C44: Pos - pos | E44: Catatan / | F44: Tidak terikat / | G44: Terikat temporer / | H44: Terikat permanen / | I44: Jumlah / | J44: Accounts
E45: Notes | F45: Unrestricted | G45: Temporarily | H45: Permanently | I45: Total
G46: restricted | H46: restricted
C47: Pendapatan dan keuntungan | K47: Revenues & gains
C48: Pendapatan pendidikan | F48: 552500000 | G48: 0 | H48: 0 | I48: =SUM(F48:H48) -> 552500000 | K48: Tuition and fees
C49: אּ | D49: Dikurangi : beasiswa | F49: -4200000 | I49: =SUM(F49:H49) -> -4200000 | J49: Less : scholarship | K49: אּ
F50: =F48+F49 -> 548300000 | G50: =SUM(G48:G49) -> 0 | H50: =SUM(H48:H49) -> 0 | I50: =I48+I49 -> 548300000
...

Sheet AK
L1: =E58 -> 0
B3: PESANTREN ISLAM AL-IRSYAD TENGARAN 6 BONDOWOSO
B5: LAPORAN ARUS KAS | J5: STATEMENTS OF CASH FLOWS
C6: =PAB!B5 -> Untuk Bulan yang Berakhir 30 June 2026 | J6: =LR!I6 -> For The Month Ended Jun 2026
B7: =[8]Nrc!B6 -> (Dengan perbandingan informasi keuangan 30 June 2023 ) | C7: =LR!C7 -> (Dengan perbandingan informasi keuangan untuk bulan yang berakhir 31 May 2026 / | J7: =LR!O7 -> With Comparative financial information for the month ended May 31, 2026 )
B9: ='[9]LR '!B9 -> (Disajikan dalam rupiah) | J9: ='[9]LR '!N9 -> (Expressed in rupiah)
C11: Uraian | E11: =NRC!E9 -> 30 June 2026/ | F11: =NRC!G9 -> 31 May 2026/ | G11: ="sd "&(E11) -> sd 30 June 2026/ | H11: Description | L11: ="sd "&(F11) -> sd 31 May 2026/
E12: =NRC!E10 -> 46203 | F12: =NRC!G10 -> 46173 | G12: =E12 -> 46203 | L12: =F12 -> 46173
C13: Arus kas dari aktivitas operasi | I13: Cash flows from operating activities
C14: Penerimaan kas dari : | I14: Cash receipt from :
C15: אּ | D15: Pendidikan santri | E15: =IF(K15<>"",SUMIF(CRAK1,K15,CRAK2),0)+IF(K15<>"",SUMIF(JMAK1,K15,JMAK2),0) -> 590502000 | F15: 662186000 | G15: =E15+L15 -> 7949850000 | H15: Tuition and fees | I15: אּ | K15: M41 | L15: 7359348000 | N15: =[8]CR!N1 -> 57351290 | O15: =E15-N15 -> 533150710
C16: אּ | D16: Sumbangan dan bantuan | E16: =IF(K16<>"",SUMIF(CRAK1,K16,CRAK2),0)+IF(K16<>"",SUMIF(JMAK1,K16,JMAK2),0) -> 0 | F16: 126385000 | G16: =E16+L16 -> 2580657300 | H16: Contributions and grants | I16: אּ | K16: M42 | L16: 2580657300
C17: אּ | D17: Kas masuk usaha pelengkap (U. Usaha) | E17: ='[10]Buku Besar'!$K$15 -> 50007700 | F17: 177492100 | G17: =E17+L17 -> 1518668400 | H17: Auxiliary enterprises cash in | I17: אּ | K17: M43 | L17: 1468660700
C18: אּ | D18: Tabungan santri | E18: =IF(K18<>"",SUMIF(CRAK1,K18,CRAK2),0)+IF(K18<>"",SUMIF(JMAK1,K18,JMAK2),0) -> 101337100 | F18: 153240700 | G18: =E18+L18 -> 1651932750 | H18: Student saving | I18: אּ | K18: M44 | L18: 1550595650 | N18: =[8]Jm!H53 -> 166740500 | O18: =E18-N18 -> -65403400
C19: אּ | D19: Pelunasan piutang lain lain | E19: =IF(K19<>"",SUMIF(CRAK1,K19,CRAK2),0)+IF(K19<>"",SUMIF(JMAK1,K19,JMAK2),0) -> 2000000 | F19: 7831615 | G19: =E19+L19 -> 21263282 | H19: Other receivable collected | I19: אּ | K19: M45 | L19: 19263282
C20: אּ | D20: Penerimaan lain lain | E20: =IF(K20<>"",SUMIF(CRAK1,K20,CRAK2),0)+IF(K20<>"",SUMIF(JMAK1,K20,JMAK2),0) -> 250100 | F20: 415118 | G20: =E20+L20 -> 4.6585912e+08 | H20: Others receipts | I20: אּ | K20: M46 | L20: 4.6560902e+08 | N20: =[8]CR!N2 -> 215130000 | O20: =E20-N20 -> -214879900
E21: =SUM(E15:E20) -> 744096900 | F21: 1127550533 | G21: =SUM(G15:G20) -> 14188230856 | L21: 13444133956
C22: Pembayaran kas kepada : | I22: Cash payment to :
C23: אּ | D23: Pemasok | E23: =IF(K23<>"",SUMIF(CDAK1,K23,CDAK2),0)+IF(K23<>"",SUMIF(JMAK1,K23,JMAK3),0) -> 133355190 | F23: 393937728 | G23: =E23+L23 -> 3955722741 | H23: Suppliers | I23: אּ | K23: K51 | L23: 3822367551 | N23: =[8]CD!N1 -> 124052605 | O23: =E23-N23 -> 9302585
C24: אּ | D24: Karyawan | E24: =IF(K24<>"",SUMIF(CDAK1,K24,CDAK2),0)+IF(K24<>"",SUMIF(JMAK1,K24,JMAK3),0) -> 266681354 | F24: 261680735 | G24: =E24+L24 -> 3402269724 | H24: Employee | I24: אּ | K24: K52 | L24: 3135588370 | N24: =[8]CD!N2 -> 25931842 | O24: =E24-N24 -> 240749512
C25: אּ | D25: Santri | E25: =IF(K25<>"",SUMIF(CDAK1,K25,CDAK2),0)+IF(K25<>"",SUMIF(JMAK1,K25,JMAK3),0) -> 122322700 | F25: 160638350 | G25: =E25+L25 -> 1398061300 | H25: Student | I25: אּ | K25: K53 | L25: 1275738600 | N25: =[8]CD!N3+[8]Jm!G52 -> 164455790 | O25: =E25-N25 -> -42133090
C26: אּ | D26: Kas keluar usaha pelengkap (U. Usaha) | E26: ='[10]Buku Besar'!$L$15 -> 92728464 | F26: 139591402 | G26: =E26+L26 -> 1490314752 | H26: Auxiliary enterprises cash out | I26: אּ | L26: 1397586288
C27: אּ | D27: Pembayaran lain lain | E27: =IF(K27<>"",SUMIF(CDAK1,K27,CDAK2),0)+IF(K27<>"",SUMIF(JMAK1,K27,JMAK3),0) -> 4200000 | F27: 74027100 | G27: =E27+L27 -> 175457128 | H27: Others payment | I27: אּ | K27: K54 | L27: 171257128
E28: =SUM(E23:E27) -> 619287708 | F28: 1029875315 | G28: =SUM(G23:G27) -> 10421825645 | L28: 9802537937
C30: Kas bersih yang diperoleh dari | I30: Net cash provided by
C31: ( digunakan untuk ) aktivitas operasi | E31: =E21-E28 -> 124809192 | F31: =F21-F28 -> 97675218 | G31: =G21-G28 -> 3766405211 | I31: ( used in ) operating activities | L31: 3641596019
C32: Arus kas dari aktivitas investasi | I32: Cash flows from investing activities
C33: Perolehan Aset tetap | E33: =IF(K33<>"",SUMIF(CDAK1,K33,CDAK2),0)+IF(K33<>"",SUMIF(JMAK1,K33,JMAK3),0) -> 1500000 | F33: 30940000 | G33: =E33+L33 -> 1775248773 | I33: Acquisition o fixed assets | K33: K50 | L33: 1773748773
C34: Hasil penjualan Aset tetap | E34: =IF(K34<>"",SUMIF(CDAK1,K34,CDAK2),0)+IF(K34<>"",SUMIF(JMAK1,K34,JMAK3),0) -> 0 | F34: 0 | G34: =SUM(E34:F34) -> 0 | I34: Proceeds from sale of fixed assets | K34: M40 | L34: 0
C35: Pembelian investasi | G35: =SUM(E35:F35) -> 0 | I35: Purchase of invesment | L35: 0
C36: Hasil penjualan investasi | E36: 0 | F36: 0 | G36: =SUM(E36:F36) -> 0 | I36: Proceeds from sale of invesment | L36: 0
C37: Kas bersih yang diperoleh dari | I37: Net cash provided by
C38: ( digunakan untuk ) aktivitas investasi | E38: =E34-E33 -> -1500000 | F38: =F34-F33 -> -30940000 | G38: =G34-G33 -> -1775248773 | I38: ( used in ) investing activities | L38: -1773748773
C39: Arus kas dari aktivitas pendanaan | I39: Cash flows from financing activities
C40: Penerimaan kas dari sumbangan terikat untuk : | I40: Cash receipt from restricted contributions for :
C41: אּ | D41: Investasi Aset tetap | E41: 0 | F41: 0 | G41: =E41+L41 -> 0 | H41: Invesment in fixed assets | I41: אּ | K41: 31 | L41: 0
C42: אּ | D42: Program jangka panjang | E42: 0 | F42: 0 | G42: =SUM(E42:F42) -> 0 | H42: Long term purpose | I42: אּ | J42: Biaya Penyusutan | K42: 32 | L42: 0
E43: =SUM(E41:E42) -> 0 | F43: 0 | G43: =SUM(G41:G42) -> 0 | L43: 0
C44: Pendapatan investasi terikat untuk | I44: Invesment income restricted for
D45: program jangka panjang | H45: Long term purpose
...

Sheet CLK
B3: PESANTREN ISLAM AL-IRSYAD TENGARAN 6 BONDOWOSO
B5: CATATAN ATAS LAPORAN KEUANGAN | AQ5: NOTES TO FINANCIAL STATEMENTS
B6: =NRC!B5 -> 30 June 2026 | AJ6: =NRC!I5 -> 46203
B7: =NRC!C6&")" -> (Dengan perbandingan informasi keuangan untuk bulan yang berakhir 31 May 2026 /) | AP7: ="("&NRC!K6 -> (With Comparative financial information for the month ended May 31, 2026 )
B8: (Disajikan dalam rupiah) | AQ8: =[9]NRC!J7 -> (Expressed in rupiah)
B9: (lanjutan) | AQ9: (continued)
B12: 1. | C12: IKHTISAR KEBIJAKAN AKUNTANSI YANG PENTING | X12: =B12 -> 1. | Y12: SUMMARY OF SIGNIFICANT ACCOUNTING POLICIES
C15: Laporan keuangan lembaga telah disusun dan diselesaikan pada 9 Agustus 2023 | Y15: ="The Istitution's financial statements were prepared and completed on"&" August" -> The Istitution's financial statements were prepared and completed on August
C16: Berikut ini adalah ikhtisar kebijakan akuntansi penting yang diterapkan dalam | Y16: ="09, 2023. Presented below are the significant accounting policies adopted in" -> 09, 2023. Presented below are the significant accounting policies adopted in
C17: penyusunan dan penyajian laporan keuangan lembaga , yang sesuai dengan prinsip | Y17: preparing and presenting the financial statements of the institution, which are
C18: dan praktek akuntansi yang berlaku umum di Indonesia. | Y18: in conformity with accounting principles and practices generally accepted
Y19: in Indonesia.
C21: a. | D21: Dasar pengukuran dan penyusunan laporan keuangan | Y21: a. | Z21: Basis of measurement and preparation of the financial statements
C34: b. | D34: Kas dan setara kas | Y34: b. | Z34: Cash and cash equivalents
C40: c. | D40: Piutang aktivitas dan lain lain | Y40: c. | Z40: Accounts and other receivables
C47: d. | D47: Persediaan | Y47: d. | Z47: Inventories
C58: e. | D58: Aset tetap | Y58: e. | Z58: Fixed assets
T67: Masa manfaat / Useful life
T68: Tahun / Years
D70: Gedung | T70: 20 | AO70: Building
D71: Infrastruktur | T71: 5 - 20 | AO71: Infrastructure
D72: Mesin dan peralatan | T72: 5 | AO72: Mechine & equipment
D73: Mebel dan perlengkapan | T73: 5 | AO73: Furniture & fixture
D74: Kendaraan | T74: 8 | AO74: Vehicles
D75: Buku & material perpustakaan | T75: 5 | AO75: Library books & material
D76: Lain lain Aset tetap | T76: 5 | AO76: Other fixed assets
C97: f. | D97: Pengakuan pendapatan dan beban | Y97: f. | Z97: Revenue and Expense Recognition
B118: Catatan atas laporan keuangan merupakan bagian yang tidak terpisahkan dari laporan keuangan | AQ118: The accompanying notes form an integral part of these financial statements
B120: =IN!C4 -> Laporan Keuangan June 2026 | W120: 6 | AQ120: =IN!D4 -> Financial Statement Jun 2026
B121: 2. | C121: KAS DAN SETARA KAS | X121: =B121 -> 2. | Y121: CASH AND CASH EQUIVALENTS
C123: Akun ini terdiri dari : | AQ123: This account consists of :
Q124: =NRC!E9 -> 30 June 2026/ | R124: =[8]IN!$G$23 -> 31 July 2023 / | S124: =[8]IN!$G$23 -> 31 July 2023 / | T124: =[8]IN!$G$23 -> 31 July 2023 / | U124: =[8]IN!$G$23 -> 31 July 2023 / | V124: =[8]IN!$G$23 -> 31 July 2023 / | X124: =NRC!G9 -> 31 May 2026/ | Y124: =[8]IN!$G$26 -> 30 June 2023 / | Z124: =[8]IN!$G$26 -> 30 June 2023 / | AA124: =[8]IN!$G$26 -> 30 June 2023 / | AB124: =[8]IN!$G$26 -> 30 June 2023 / | AC124: =[8]IN!$G$26 -> 30 June 2023 /
Q125: =NRC!E10 -> 46203 | R125: =[8]IN!$I$23 -> #N/A | S125: =[8]IN!$I$23 -> #N/A | T125: =[8]IN!$I$23 -> #N/A | U125: =[8]IN!$I$23 -> #N/A | V125: =[8]IN!$I$23 -> #N/A | X125: =NRC!G10 -> 46173 | Y125: =[8]IN!$I$26 -> #N/A | Z125: =[8]IN!$I$26 -> #N/A | AA125: =[8]IN!$I$26 -> #N/A | AB125: =[8]IN!$I$26 -> #N/A | AC125: =[8]IN!$I$26 -> #N/A
C126: Kas | AQ126: Cash on hand
C127: אּ | D127: Kas ditangan | Q127: =BS!C17 -> 919800 | X127: 1885900 | AP127: Cash - central | AQ127: אּ | AS127: 1-1111 | AT127: Education Cash
C128: אּ | D128: Kas Kantin 6 Mart | Q128: ='12'!E14+'12'!E15 -> 2.2306116e+08 | X128: 2.6578192e+08 | AP128: Cash - auxiliary enterprise | AQ128: אּ
C129: אּ | D129: Kas tabungan | Q129: =BS!C18 -> 85600 | X129: 101107200 | AP129: Cash - saving student | AQ129: אּ | AS129: 1-1112 | AT129: Student Saving Cash
C130: אּ | D130: Kas BOS SD Diknas | Q130: 0 | X130: 0 | AP130: Cash - BOS SDITQ | AQ130: אּ
C131: אּ | D131: Kas BOS MTS Depag | Q131: =BS!C20 -> 175654800 | X131: 183016600 | AP131: Cash - BOS MTS Depag | AQ131: אּ
C132: אּ | D132: Kas BOS IM Depag | Q132: =BS!C21 -> 161988900 | X132: 168205300 | AP132: Cash - BOS MA Depag | AQ132: אּ | AS132: =X128-Q128 -> 42720764
...

Sheet 1
C1: 2 | D1: 3 | E1: 4 | F1: 5 | G1: 6 | H1: 7 | I1: 8 | J1: 9 | K1: 10 | L1: 11
A2: =CLK!B3 -> PESANTREN ISLAM AL-IRSYAD TENGARAN 6 BONDOWOSO
A4: LAMPIRAN 1 / APPENDIX 1
A5: RINCIAN PIUTANG UANG PENDIDIKAN | L5: DETAILS OF TUITION AND FEE RECEIVABLE
A6: =NRC!B5 -> 30 June 2026 | L6: =NRC!I5 -> 46203
A7: =NRC!C6 -> (Dengan perbandingan informasi keuangan untuk bulan yang berakhir 31 May 2026 / | L7: =NRC!K6 -> With Comparative financial information for the month ended May 31, 2026 )
A8: (Disajikan dalam Rupiah) | L8: (Expressed in rupiah)
A9: (lanjutan) | L9: (continued)
A11: No./ | B11: Uraian / | D11: Kelas / | E11: =NRC!E9 & (IN!D5) -> 30 June 2026/46203 | L11: =NRC!E9 -> 30 June 2026/ | S11: Tgl Invoice | T11: Nama sales | U11: Jumlah | V11: Pembayaran I | Y11: Pembayaran II | AB11: Pembayaran III | AG11: Jumlah
B12: Description | D12: Class | E12: SPP / | F12: Ektra k. / | G12: Dana gedung | H12: D.Perpustakaan | I12: Daftar ulang / | J12: B & Seragam | K12: Jumlah / | L12: =NRC!E10 -> 46203
E13: Tuition | F13: Extra c. | G13: Building fund / | H13: Library fund | I13: Enrollment | J13: B & Uniform | K13: Total
B14: PIUTANG SANTRI / STUDENT RECEIVABLE
C15: MTS / Islamic junior high school
C16: Kelas VII / Class VII
B17: 1 | C17: ABDUL GHOWI TAMIM IMRAN | D17: MTW VII | E17: 15900000 | F17: 0 | G17: 15300000 | H17: 0 | I17: 0 | J17: 0 | K17: =SUM(E17:J17) -> 31200000
B18: 2 | C18: AHNAF ISMAIL AL FAQIH | D18: MTW VII | E18: 0 | F18: 0 | G18: 10500000 | H18: 0 | I18: 0 | J18: 0 | K18: =SUM(E18:J18) -> 10500000
B19: 3 | C19: FAHRI | D19: MTW VII | E19: 500000 | F19: 0 | G19: 0 | H19: 0 | I19: 0 | J19: 0 | K19: =SUM(E19:J19) -> 500000
B20: 4 | C20: ZUBAIR RAJAB | D20: MTW VII | E20: 0 | F20: 0 | G20: 4600000 | H20: 0 | I20: 0 | J20: 0 | K20: =SUM(E20:J20) -> 4600000
B21: 5 | K21: =SUM(E21:J21) -> 0
B22: 6 | K22: =SUM(E22:J22) -> 0
B23: 7 | K23: =SUM(E23:J23) -> 0
B24: 8 | K24: =SUM(E24:J24) -> 0
B25: 9 | K25: =SUM(E25:J25) -> 0
B26: 10 | K26: =SUM(E26:J26) -> 0
B27: 11 | K27: =SUM(E27:J27) -> 0
B28: 12 | K28: =SUM(E28:J28) -> 0
B29: 13 | K29: =SUM(E29:J29) -> 0
B30: 14 | K30: =SUM(E30:J30) -> 0
B31: 15 | K31: =SUM(E31:J31) -> 0
B32: 16 | K32: =SUM(E32:J32) -> 0
... B36: 20 | K36: =SUM(E36:J36) -> 0
E37: =SUM(E17:E36) -> 16400000 | F37: =SUM(F17:F36) -> 0 | G37: =SUM(G17:G36) -> 30400000 | H37: =SUM(H17:H36) -> 0 | I37: =SUM(I17:I36) -> 0 | J37: =SUM(J17:J36) -> 0 | K37: =SUM(K17:K36) -> 46800000
C38: Kelas VIII / Class VIII
B39: 1 | C39: Ahmad Adnan Bayasyut | D39: MTW VIII | E39: 3400000 | F39: 0 | G39: 0 | H39: 0 | I39: 0 | J39: 0 | K39: =SUM(E39:J39) -> 3400000
B40: 2 | C40: Darrell Attharizt Zaidan Alvaro | D40: MTW VIII | E40: 4200000 | F40: 0 | G40: 0 | H40: 0 | I40: 0 | J40: 0 | K40: =SUM(E40:J40) -> 4200000
B41: 3 | C41: Fahri Balafif | D41: MTW VIII | E41: 0 | F41: 0 | G41: 0 | H41: 0 | I41: 2166000 | J41: 0 | K41: =SUM(E41:J41) -> 2166000
B42: 4 | C42: Fahri Muhamad Bakrak | D42: MTW VIII | E42: 600000 | F42: 0 | G42: 0 | H42: 0 | I42: 0 | J42: 0 | K42: =SUM(E42:J42) -> 600000
B43: 5 | C43: Fandi Azwana Ibrahim | D43: MTW VIII | E43: 14450000 | F43: 0 | G43: 11300000 | H43: 0 | I43: 1416000 | J43: 0 | K43: =SUM(E43:J43) -> 27166000
B44: 6 | C44: Fawwaz Tamim Imran | D44: MTW VIII | E44: 3700000 | F44: 0 | G44: 0 | H44: 0 | I44: 100000 | J44: 0 | K44: =SUM(E44:J44) -> 3800000
B45: 7 | C45: Fikri Akid | D45: MTW VIII | E45: 5100000 | F45: 0 | G45: 0 | H45: 0 | I45: 0 | J45: 0 | K45: =SUM(E45:J45) -> 5100000
...

Sheet 2
A2: =NRC!B2 -> PESANTREN ISLAM AL-IRSYAD TENGARAN 6 BONDOWOSO
A4: LAMPIRAN 2 / APPENDIX 2
A5: RINCIAN PIUTANG LAIN LAIN | F5: DETAILS OF OTHER ACCOUNT RECEIVABLES
A6: =NRC!B5 -> 30 June 2026 | F6: =NRC!I5 -> 46203
A7: =NRC!C6 -> (Dengan perbandingan informasi keuangan untuk bulan yang berakhir 31 May 2026 / | F7: =NRC!K6 -> With Comparative financial information for the month ended May 31, 2026 )
A8: =+[12]NRC!B7 -> (Disajikan dalam rupiah) | F8: =+[12]NRC!J7 -> (Expressed in rupiah)
A9: (lanjutan) | F9: (continued)
A11: No. | B11: Uraian / | D11: =NRC!E9 -> 30 June 2026/ | E11: =NRC!G9 -> 31 May 2026/ | F11: Keterangan / | J11: No | K11: Nama Customer | L11: No Invoice | M11: Tgl Invoice | N11: Nama sales | O11: Jumlah | P11: Pembayaran I | S11: Pembayaran II | V11: Pembayaran III | AA11: Jumlah
A12: No. | B12: Desrciption | D12: =NRC!E10 -> 46203 | E12: =NRC!G10 -> 46173 | F12: Remark
A13: 1. | B13: PIUTANG KARYAWAN / EMPLOYEE RECEIVABLE
B14: PIAT
B15: 1 | C15: AHMAD WARDIYANTO | D15: 0 | E15: 300000
B16: 2 | C16: BENI SETIAWAN | D16: 0 | E16: 2400000
B17: 3 | C17: Husein Bafadal | D17: 0 | E17: 1000000
B18: 4 | C18: HARIS MAULANA ISHAQ | D18: 241666.67 | E18: 483333.33
B19: 5 | C19: HANIF MUFTI AL ISLAM | D19: 750000 | E19: 1000000
B20: 6 | C20: NANANG SUGIANTO | D20: 250000 | E20: 1000000
B21: 7 | C21: YOGA NUGRAHA PERMANA (Potong Mulai 5 Des 25) | D21: 1250000 | E21: 1500000
B22: 8 | C22: JUALI EFENDI | D22: 1083333.3 | E22: 1300000
B23: 9 | C23: AJI MAULANA MAJID | D23: 1666666.7 | E23: 2000000
B24: 10 | C24: RIZAL HABIBULLOH (Potong mulai Jan 26) | D24: 1000000 | E24: 2000000
B25: 11 | C25: FARIS | D25: 4000000 | E25: 5000000
B26: 12 | C26: BABUN AGUS TIANTORO | D26: 3500000 | E26: 4000000
... B43: 29 | C43: UMAR | D43: 10768470 | E43: 11747422
B44: 30 | C44: MUHAMMAD ARIF ARIWAKRI | D44: 4000000
B45: 31 | C45: BENI SETIAWAN | D45: 4000000
B46: 32 | C46: FIRDAUS AL'ROSI | D46: 7000000
B47: 33 | C47: IRZADULIBAD | D47: 3600000
B48: 34 | C48: MARWA ROFIQUL ILHAM (Potong Mulai 1 Agustus) | D48: 3000000
D50: =SUM(D15:D49) -> 76049804 | E50: =SUM(E15:E49) -> 69053505
G51: 11429
B52: Lain-lain karyawan / Other employee
B53: 1
B54: 2
D55: =SUM(D53:D54) -> 0 | E55: =SUM(E53:E54) -> 0
A57: Jumlah piutang karyawan / Total employee receivable | D57: =D50+D55 -> 76049804 | E57: =+E48+E55 -> 0 | H57: Untuk eliminasi
A58: 2. | B58: PINJAMAN SANTRI / STUDENT LOAN | G58: =D66-E66 -> 0 | H58: ='[12]14'!I111 -> 1819992316 | I58: ='[12]6'!$F$715 -> 576584225
B59: 1 | C59: Pinjaman Santri | D59: 0 | E59: 0
B60: 2 | C60: Kelebihan pembayaran tabungan
B61: 3 | C61: Piutang tabungan yusran | G61: ='[12]30'!V20 -> 6.6889448e+09
...

Sheet 3
A2: =NRC!B2 -> PESANTREN ISLAM AL-IRSYAD TENGARAN 6 BONDOWOSO | M2: 181
A4: LAMPIRAN 3 / APPENDIX 3
A5: RINCIAN PERSEDIAAN | I5: DETAIL OF INVENTORIES
A6: =NRC!B5 -> 30 June 2026 | I6: =NRC!I5 -> 46203 | L6: 123721327
A7: =NRC!C6 -> (Dengan perbandingan informasi keuangan untuk bulan yang berakhir 31 May 2026 / | I7: =NRC!K6 -> With Comparative financial information for the month ended May 31, 2026 ) | L7: 213250750
A8: =+[12]NRC!B7 -> (Disajikan dalam rupiah) | I8: =+[12]NRC!J7 -> (Expressed in rupiah)
A9: (lanjutan) | I9: (continued) | K9: 37929540
A11: No. / | B11: Uraian / | C11: Satuan / | D11: =NRC!E9 -> 30 June 2026/ | G11: =NRC!G9 -> 31 May 2026/
A12: No. | B12: Description | C12: Unit | D12: Harga / Price | E12: Qty. | F12: Jumlah / Total | G12: Harga / Price | H12: Qty. | I12: Jumlah / Total
A13: 1 | B13: Buku dan seragam / Books and uniform
A14: 1 | B14: Persediaan seragam Kain Batik & Kain Guru | K14: =SUM(#REF!)-6958000-750000 -> #REF! | L14: ada buku bantu
A15: 2 | B15: Persediaan seragam santri 22/23 | F15: 34870000 | I15: 34870000
A16: 3 | B16: Persediaan Buku santri 22/23 | F16: 38180496 | I16: 38180496
A17: 4 | B17: Persediaan seragam santri 26/27 | D17: 12110000 | E17: 1 | F17: =D17*E17 -> 12110000 | I17: =G17*H17 -> 0
A18: 5 | B18: Persediaan Buku santri 26/27 | D18: 35528685 | E18: 1 | F18: =D18*E18 -> 35528685 | I18: =G18*H18 -> 0
A19: 6 | B19: Sprei dan Sarung Bantal | D19: 75000 | E19: 100 | F19: =D19*E19 -> 7500000 | G19: 75000 | H19: 100 | I19: =G19*H19 -> 7500000
A20: 7 | B20: Bantal | D20: 32290 | E20: 100 | F20: =D20*E20 -> 3229000 | G20: 32290 | H20: 100 | I20: =G20*H20 -> 3229000 | K20: K291225
F21: =SUM(F14:F20) -> 131418181 | I21: =SUM(I14:I20) -> 83779496 | K21: =F21-I21 -> 47638685
A22: 2 | B22: Alat tulis kantor / Stationary
A23: 1 | B23: Ballpoint - 4 Warna | C23: Biji | F23: =D23*E23 -> 0 | I23: =G23*H23 -> 0
A24: 2 | B24: Ballpoint ( Biru ) | C24: Biji | F24: =D24*E24 -> 0 | I24: =G24*H24 -> 0
A25: 3 | B25: Ballpoint ( Hitam ) | C25: Dus | F25: =D25*E25 -> 0 | I25: =G25*H25 -> 0
A26: 4 | B26: Ballpoint ( Merah ) | C26: Biji | F26: =D26*E26 -> 0 | I26: =G26*H26 -> 0
A27: 5 | B27: Ballpoint Meja | C27: Biji | F27: =D27*E27 -> 0 | I27: =G27*H27 -> 0
A28: 6 | B28: Ballpoint R5/ ACTION ( Hitam ) | C28: Biji | F28: =D28*E28 -> 0 | I28: =G28*H28 -> 0
A29: 7 | B29: Boxi / TIZO ( Hitam ) | C29: Biji | F29: =D29*E29 -> 0 | I29: =G29*H29 -> 0
A30: 8 | B30: Pencil TIC | C30: Biji | F30: =D30*E30 -> 0 | I30: =G30*H30 -> 0
A31: 9 | B31: Drawing pen 0,5 mm | C31: Biji | F31: =D31*E31 -> 0 | I31: =G31*H31 -> 0
A32: 10 | B32: Ballpoint PILOT | C32: Biji | F32: =D32*E32 -> 0 | I32: =G32*H32 -> 0
D34: =SUM(D23:D33) -> 0 | E34: =SUM(E23:E33) -> 0 | F34: =SUM(F23:F33) -> 0 | G34: =SUM(G23:G32) -> 0 | H34: =SUM(H23:H32) -> 0 | I34: =SUM(I23:I32) -> 0 | K34: =F34-F35 -> -13778617
A35: 3 | B35: Obat - obatan / Medicines | E35: =[13]ATK!$V$343 -> 6112 | F35: =[14]ATK!$AL$344 -> 13778617 | L35: =E34-E35 -> -6112
A37: 1 | B37: BENANG JAHIT CROMIC | C37: tablet | F37: =D37*E37 -> 0 | I37: =G37*H37 -> 0 | J37: OG101
A38: 2 | B38: BENANG JAHIT CUTGUT | C38: tablet | F38: =D38*E38 -> 0 | I38: =G38*H38 -> 0 | J38: OG102
A39: 3 | B39: BENANG JAHIT SILK | C39: Tube | F39: =D39*E39 -> 0 | I39: =G39*H39 -> 0 | J39: OG301
A40: 4 | B40: DARYANTULE | C40: tablet | F40: =D40*E40 -> 0 | I40: =G40*H40 -> 0 | J40: OB101
A41: 5 | B41: ELASTIS PERBAN | C41: tablet | F41: =D41*E41 -> 0 | I41: =G41*H41 -> 0 | J41: OB102
A42: 6 | B42: HANDSCONE | C42: tablet | F42: =D42*E42 -> 0 | I42: =G42*H42 -> 0 | J42: OB103
A43: 7 | B43: HYGENIK 500 ML | C43: tablet | F43: =D43*E43 -> 0 | I43: =G43*H43 -> 0 | J43: OB104
A44: 8 | B44: JARUM JAHIT | C44: tablet | F44: =D44*E44 -> 0 | I44: =G44*H44 -> 0 | J44: OB105
A45: 9 | B45: KAPAS 1KG | C45: tablet | F45: =D45*E45 -> 0 | I45: =G45*H45 -> 0 | J45: OB106
...

Sheet 4
A2: PESANTREN ISLAM AL-IRSYAD, TENGARAN
A5: RINCIAN ASET TETAP
A6: 45138
A7: (Dengan perbandingan informasi keuangan 30 Juni 2023 )
A8: (Disajikan dalam rupiah)
A10: No./No. | C10: Uraian / | D10: Lokasi / | E10: Tanggal | F10: Referansi | G10: Qty | H10: UE | I10: Jumlah | J10: Tarif | K10: Harga satuan | L10: Harga perolehan / Acquisition cost | P10: Akumulasi penyusutan / Accumulated depreciation | T10: Nilai buku bersih
C11: Description | D11: Location | L11: =IN!C8 -> 31 May 2026 | M11: Penambahan & | N11: Pengurangan & | O11: =IN!C5 -> 30 June 2026 | P11: =L11 -> 31 May 2026 | Q11: Penambahan & | R11: Pengurangan & | S11: =O11 -> 30 June 2026 | T11: =S11 -> 30 June 2026
M12: reklasifikasi / | N12: reklasifikasi / | Q12: reklasifikasi / | R12: reklasifikasi /
M13: Additions & | N13: Deductions & | Q13: Additions & | R13: Deductions &
M14: reclassification | N14: reclassification | Q14: reclassification | R14: reclassification
A16: 1 | B16: Tanah / Land
B17: 1 | C17: TANAH | D17: PIAT 6 | E17: 44742 | G17: 1 | K17: 2820000000 | L17: 2820000000 | O17: =L17+M17-N17 -> 2820000000 | P17: 0 | S17: 0 | T17: =O17-S17 -> 2820000000 | U17: 1
B18: 2 | C18: TANAH | D18: PIAT 6 | E18: 44834 | G18: 1 | K18: 286270000 | L18: 286270000 | O18: =L18+M18-N18 -> 286270000 | P18: 0 | S18: 0 | T18: =O18-S18 -> 286270000 | U18: 1
B19: 3 | C19: TANAH (Angga Purnama Sari) | D19: PIAT 6 | E19: 44957 | G19: 1 | K19: 253700000 | L19: 253700000 | O19: =L19+M19-N19 -> 253700000 | S19: 0 | T19: =O19-S19 -> 253700000 | U19: 1
B20: 4 | C20: TANAH (DP1) Deny Haji Cung | D20: PIAT 6 | E20: 45293 | F20: CK030124 | G20: 1 | K20: 30000000 | L20: 30000000 | O20: =L20+M20-N20 -> 30000000 | S20: 0 | T20: =O20-S20 -> 30000000 | U20: 1
B21: 5 | C21: TANAH (DP2) Deny Haji Cung | D21: PIAT 6 | E21: 45293 | F21: K010124 | G21: 1 | K21: 20000000 | L21: 20000000 | O21: =L21+M21-N21 -> 20000000 | S21: 0 | T21: =O21-S21 -> 20000000 | U21: 1
B22: 6 | C22: TANAH (DP3) Deny Haji Cung | D22: PIAT 6 | E22: 45350 | F22: CK | G22: 1 | K22: 174000000 | L22: 174000000 | O22: =L22+M22-N22 -> 174000000 | S22: 0 | T22: =O22-S22 -> 174000000 | U22: 1
B23: 7 | C23: TANAH (Pelunasan) Deny Haji Cung | D23: PIAT 6 | E23: 45777 | F23: CK040425 | G23: 1 | K23: 300000000 | L23: 300000000 | O23: =L23+M23-N23 -> 300000000 | T23: =O23-S23 -> 300000000 | U23: 1
C25: TOTAL LAND | L25: =SUM(L17:L23) -> 3883970000 | M25: =SUM(M17:M23) -> 0 | N25: =SUM(N17:N23) -> 0 | O25: =SUM(O17:O23) -> 3883970000 | P25: 0 | Q25: =SUM(Q17:Q23) -> 0 | R25: =SUM(R17:R23) -> 0 | S25: =SUM(S17:S23) -> 0 | T25: =SUM(T17:T23) -> 3883970000
A26: 2 | B26: Gedung / Building
B27: 1 | C27: Building - Class & Office
B28: 1 | C28: Gedung Kelas | D28: PIAT 6 | E28: 43647 | G28: 1 | H28: 20 | I28: 240 | J28: 7083333.3 | K28: 1700000000 | L28: 1700000000 | O28: =L28+M28-N28 -> 1700000000 | P28: 5.8791667e+08 | Q28: =J28 -> 7083333.3 | S28: =P28+Q28-R28 -> 5.95e+08 | T28: =O28-S28 -> 1.105e+09 | U28: 3
B29: 2 | C29: GEDUNG KELAS | D29: PIAT 7 | E29: 44743 | G29: 1 | H29: 20 | I29: =12*H29 -> 240 | J29: =K29/I29 -> 8090218.8 | K29: 1941652520 | L29: 1941652520 | O29: =L29+M29-N29 -> 1941652520 | P29: 3.8024029e+08 | Q29: =J29 -> 8090218.8 | S29: =P29+Q29-R29 -> 3.883305e+08 | T29: =O29-S29 -> 1.553322e+09 | U29: 3
B30: 2 | C30: Kantor EXT | D30: PIAT 8 | E30: 45179 | G30: 1 | H30: 20 | I30: 240 | J30: =K30*G30/I30 -> 2229720 | K30: 535132800 | L30: =K30 -> 535132800 | O30: =L30+M30-N30 -> 535132800 | P30: 42364680 | Q30: =J30 -> 2229720 | S30: =P30+Q30-R30 -> 44594400 | T30: =O30-S30 -> 490538400 | U30: 3
B31: 3 | L31: 0 | O31: =L31+M31-N31 -> 0 | P31: 0 | Q31: =J31 -> 0 | S31: =P31+Q31-R31 -> 0 | T31: =O31-S31 -> 0 | U31: 3
B32: 3 | L32: 0 | O32: =L32+M32-N32 -> 0 | P32: 0 | Q32: =J32 -> 0 | S32: =P32+Q32-R32 -> 0 | T32: =O32-S32 -> 0 | U32: 3
J33: =SUM(J28:J32) -> 17403272 | K33: =SUM(K28:K32) -> 4176785320 | L33: =SUM(L28:L32) -> 4176785320 | M33: =SUM(M28:M32) -> 0 | N33: =SUM(N28:N32) -> 0 | O33: =SUM(O28:O32) -> 4176785320 | P33: =SUM(P28:P32) -> 1.0105216e+09 | Q33: =SUM(Q28:Q32) -> 17403272 | ... T33: =SUM(T28:T32) -> 3.1488604e+09
B34: 2 | C34: Building - Boarding
B35: 1 | C35: ASRAMA | D35: PIAT 6 | E35: 45260 | G35: 1 | H35: 20 | I35: 240 | J35: =K35*G35/I35 -> 13408750 | K35: 3218100000 | L35: =K35 -> 3218100000 | O35: =L35+M35-N35 -> 3218100000 | P35: 254766250 | Q35: =J35 -> 13408750 | S35: =P35+Q35-R35 -> 268175000 | T35: =O35-S35 -> 2949925000 | U35: 4
B36: 2 | U36: 4
B37: 3 | L37: 0 | O37: =L37+M37-N37 -> 0 | P37: 0 | Q37: =J37 -> 0 | S37: =P37+Q37-R37 -> 0 | T37: =O37-S37 -> 0 | U37: 4
J38: =SUM(J35:J37) -> 13408750 | K38: =SUM(K35:K37) -> 3218100000 | L38: =SUM(L35:L37) -> 3218100000 | M38: =SUM(M35:M37) -> 0 | N38: =SUM(N35:N37) -> 0 | O38: =SUM(O35:O37) -> 3218100000 | P38: =SUM(P35:P37) -> 254766250 | Q38: =SUM(Q35:Q37) -> 13408750 | ... T38: =SUM(T35:T37) -> 2949925000
B39: 3 | C39: Building - Housing
B40: 1 | C40: RUMAH GURU | E40: 43647 | G40: 2 | H40: 20 | I40: =12*H40 -> 240 | J40: =K40*G40/I40 -> 1083333.3 | K40: 130000000 | L40: =K40*G40 -> 260000000 | O40: =L40+M40-N40 -> 260000000 | P40: 89916667 | Q40: =J40 -> 1083333.3 | S40: =P40+Q40-R40 -> 91000000 | T40: =O40-S40 -> 1.69e+08 | U40: 5
B41: 2 | C41: RUMAH BUJANG & UKS | E41: 45350 | G41: 1 | H41: 20 | I41: 240 | J41: =K41*G41/I41 -> 3269275 | K41: 784626000 | L41: =K41*G41 -> 784626000 | O41: =L41+M41-N41 -> 784626000 | P41: 62116225 | Q41: =J41 -> 3269275 | S41: =P41+Q41-R41 -> 65385500 | T41: =O41-S41 -> 719240500 | U41: 5
B42: 3 | O42: =L42+M42-N42 -> 0 | P42: 0 | Q42: =J42 -> 0 | S42: =P42+Q42-R42 -> 0 | T42: =O42-S42 -> 0 | U42: 5
B43: 4 | U43: 5
J44: =SUM(J40:J43) -> 4352608.3 | K44: =SUM(K40:K43) -> 914626000 | L44: =SUM(L40:L43) -> 1044626000 | M44: =SUM(M40:M43) -> 0 | N44: =SUM(N40:N43) -> 0 | O44: =SUM(O40:O43) -> 1044626000 | P44: =SUM(P40:P43) -> 1.5203289e+08 | Q44: =SUM(Q40:Q43) -> 4352608.3 | ... T44: =SUM(T40:T43) -> 888240500
B45: 4 | C45: Building - Masjid
B46: 1 | C46: MASJID Ditambah Ke masjid no.3 Bulan Oktober 2025 | D46: PIAT 6 | E46: 43647 | G46: 1 UNIT | H46: 20 | I46: 240 | J46: 2725387.9 | K46: 654093087 | L46: 654093087 | O46: =L46+M46-N46 -> 654093087 | P46: 2.2620719e+08 | Q46: 2725387.9 | S46: =P46+Q46-R46 -> 2.2893258e+08 | T46: =O46-S46 -> 4.2516051e+08 | U46: 6
...

Sheet 5
C1: 2 | D1: 3 | E1: 4 | F1: 5 | G1: 6 | H1: 7 | I1: 8
A2: =NRC!B2 -> PESANTREN ISLAM AL-IRSYAD TENGARAN 6 BONDOWOSO
A4: LAMPIRAN 5 / APPENDIX 5
A5: RINCIAN TITIPAN UANG PENDIDIKAN | I5: DETAIL OF TUITION AND FEE DEPOSIT
A6: ='1'!A6 -> 30 June 2026 | I6: ='1'!L6 -> 46203
A7: ='1'!A7 -> (Dengan perbandingan informasi keuangan untuk bulan yang berakhir 31 May 2026 / | I7: ='1'!L7 -> With Comparative financial information for the month ended May 31, 2026 )
A8: (Disajikan dalam Rupiah) | I8: (Expressed in rupiah)
A9: (lanjutan) | I9: (continued)
A11: No./ | B11: Uraian / | D11: Kelas / | E11: =H11 -> 30 June 2026/ | H11: ='1'!L11 -> 30 June 2026/ | I11: Keterangan /
B12: Description | D12: Class | E12: SPP / | F12: Ektra k. / | G12: Jumlah / | H12: ='1'!L12 -> 46203 | I12: Remark
E13: Tuition | F13: Extra c. | G13: Total
A15: 1. | B15: TITIPAN SANTRI / STUDENT RECEIVABLE
C16: MTS / Islamic junior high school
C17: Kelas VII / Class VII
B18: 1 | C18: ALRASYID MAHARDIKA AFANDI | D18: MTW VII | E18: 1900000 | G18: =SUM(E18:F18) -> 1900000 | H18: =G18 -> 1900000
B19: 2 | C19: ALVARO ABDILLAH PRATAMA | D19: MTW VII | E19: 1900000 | G19: =SUM(E19:F19) -> 1900000 | H19: =G19 -> 1900000
B20: 3 | C20: MUHAMMAD ZAHIR | D20: MTW VII | E20: 1050000 | G20: =SUM(E20:F20) -> 1050000 | H20: =G20 -> 1050000
B21: 4 | G21: =SUM(E21:F21) -> 0 | H21: =G21 -> 0
B22: 5 | G22: =SUM(E22:F22) -> 0 | H22: =G22 -> 0
B23: 6 | G23: =SUM(E23:F23) -> 0 | H23: =G23 -> 0
B24: 7 | G24: =SUM(E24:F24) -> 0 | H24: =G24 -> 0
B25: 8 | G25: =SUM(E25:F25) -> 0 | H25: =G25 -> 0
B26: 9 | G26: =SUM(E26:F26) -> 0 | H26: =G26 -> 0
B27: 10 | G27: =SUM(E27:F27) -> 0 | H27: =G27 -> 0
B28: 11 | G28: =SUM(E28:F28) -> 0 | H28: =G28 -> 0
B29: 12 | G29: =SUM(E29:F29) -> 0 | H29: =G29 -> 0
B30: 13 | G30: =SUM(E30:F30) -> 0 | H30: =G30 -> 0
B31: 14 | G31: =SUM(E31:F31) -> 0 | H31: =G31 -> 0
B32: 15 | G32: =SUM(E32:F32) -> 0 | H32: =G32 -> 0
... B37: 20 | G37: =SUM(E37:F37) -> 0 | H37: =G37 -> 0
E38: =SUM(E18:E37) -> 4850000 | F38: =SUM(F18:F37) -> 0 | G38: =SUM(G18:G37) -> 4850000 | H38: =SUM(H18:H37) -> 4850000
C39: Kelas VIII / Class VIII
B40: 1 | C40: Arkaan Dewa Fauzaan | D40: MTW VIII | E40: 1900000 | G40: =SUM(E40:F40) -> 1900000 | H40: =G40 -> 1900000
B41: 2 | C41: Izzatul Ibad | D41: MTW VIII | E41: 22800000 | G41: =SUM(E41:F41) -> 22800000 | H41: =G41 -> 22800000
B42: 3 | C42: Muhammad Aidan Maheswara | D42: MTW VIII | E42: 1900000 | G42: =SUM(E42:F42) -> 1900000 | H42: =G42 -> 1900000
B43: 4 | C43: Muhammad As Silmi Sulaiman | D43: MTW VIII | E43: 1900000 | G43: =SUM(E43:F43) -> 1900000 | H43: =G43 -> 1900000
B44: 5 | C44: Muhammad Faisal Rasyid | D44: MTW VIII | E44: 1900000 | G44: =SUM(E44:F44) -> 1900000 | H44: =G44 -> 1900000
B45: 6 | C45: Muhammad Fauzan Fahriansha | D45: MTW VIII | E45: 1900000 | G45: =SUM(E45:F45) -> 1900000 | H45: =G45 -> 1900000
B46: 7 | G46: =SUM(E46:F46) -> 0 | H46: =G46 -> 0
B47: 9 | G47: =SUM(E47:F47) -> 0 | H47: =G47 -> 0
...

Sheet 6
A2: =NRC!B2 -> PESANTREN ISLAM AL-IRSYAD TENGARAN 6 BONDOWOSO
A4: LAMPIRAN 6 / APPENDIX 6
A5: RINCIAN TITIPAN LAIN LAIN | H5: DETAIL OF OTHER DEPOSITS
A6: =NRC!B5 -> 30 June 2026 | G6: =NRC!I5 -> 46203
A7: =NRC!C6 -> (Dengan perbandingan informasi keuangan untuk bulan yang berakhir 31 May 2026 / | H7: =NRC!K6 -> With Comparative financial information for the month ended May 31, 2026 )
A8: (Disajikan dalam Rupiah) | H8: (Expressed in rupiah)
A9: (lanjutan) | H9: (continued)
A11: No. / | B11: Uraian / | F11: ='2'!D11 -> 30 June 2026/ | G11: ='2'!E11 -> 31 May 2026/ | H11: Keterangan
A12: No. | B12: Description | F12: ='2'!D12 -> 46203 | G12: ='2'!E12 -> 46173 | H12: Remark | L12: No | M12: Nama Customer | N12: No Invoice | O12: Tgl Invoice | P12: Nama sales | Q12: Jumlah | R12: Pembayaran I | U12: Pembayaran II | X12: Pembayaran III | AC12: Jumlah
A13: 1. | B13: Kiriman bank / Bank transfer
B14: Kiriman BMI - pending / BMI transfer - pending
B15: 1 | C15: Transfer | F15: 1300000 | G15: 1300000
B16: 2
B17: 3
B18: 4
B19: 5
B20: 6
B21: 7
B22: 8
B23: 9
B24: 10
B25: 11
B26: 12
B27: 13
... B30: 16
F33: =SUM(F15:F32) -> 1300000 | G33: =SUM(G15:G32) -> 1300000
B34: Kiriman GIRO BMI - pending / BMI transfer - pending | I34: =F33-I33 -> 1300000
B35: 1 | C35: Tranfer BMI Pesantren | D35: 45597 | F35: 150000 | G35: 150000
B36: 2 | C36: Tranfer Giro BMI | D36: 45635 | F36: =500000-500000 -> 0 | G36: 0 | H36: Muhammad Yusuf (VII)
B37: 3 | C37: Tranfer Giro BMI Flips | D37: 45818 | F37: =4500000-4500000 -> 0 | G37: 0 | H37: Muhammad Yusuf (VII)
B38: 4 | C38: Tranfer GIRO BMI (RIZKY FARIZA ) | D38: 45840 | F38: =1000000-1000000 -> 0 | G38: 1000000 | H38: Donasi
B39: 5 | C39: Tranfer GIRO BMI | D39: 45857 | F39: 0 | G39: 0 | H39: Wildan Farid Hamadah
B40: 6 | C40: Tranfer GIRO BMI | D40: 45873 | F40: =5000000-5000000 -> 0 | G40: 0 | H40: Donasi Pengeboran Kelas Baru
B41: 7
B42: 8
B43: 9
B44: 10
F46: =SUM(F35:F45) -> 150000 | G46: =SUM(G35:G45) -> 1150000 | I46: ='[16]AGT-23'!$W$2804 -> 56711946 | J46: =F46-I46 -> -56561946
A47: Jumlah kiriman bank / Total bank transfer | F47: =+F46+F33 -> 1450000 | G47: =+G46+G33 -> 2450000
A48: 2. | B48: Kelebihan pembayaran / Excess payment | J48: l
...

Sheet 7
A1: =NRC!B2 -> PESANTREN ISLAM AL-IRSYAD TENGARAN 6 BONDOWOSO
A2: RINCIAN BIAYA MASIH HARUS DIBAYAR | G2: DETAIL OF ACCRUED EXPENSES
A3: =NRC!B5 -> 30 June 2026 | G3: =NRC!I5 -> 46203
A4: ='5'!A7 -> (Dengan perbandingan informasi keuangan untuk bulan yang berakhir 31 May 2026 / | G4: =NRC!K6 -> With Comparative financial information for the month ended May 31, 2026 )
A5: =NRC!B7 -> (Disajikan dalam rupiah) | G5: =NRC!K7 -> (Expressed in rupiah)
A6: (lanjutan) | G6: (continued)
